Workbook

Sheet Raw Data
A1: Row ID | B1: Order ID | C1: Order Date | D1: Clean Date | E1: Month | F1: Ship Date | G1: Ship Mode | H1: Customer ID | I1: Segment | J1: Country | K1: City | L1: State | M1: Region | N1: Product ID | O1: Category | P1: Sub-Category | Q1: Product Name | R1: Sales | S1: Quantity | T1: Discount | U1: Profit
A2: 1 | B2: CA-2016-152156 | C2: 42593 | D2: =IF(ISNUMBER(C2),C2,DATE(VALUE(RIGHT(C2,4)),VALUE(LEFT(C2,FIND("/",C2)-1)),VALUE(MID(C2,FIND("/",C2)+1,FIND("/",C2,FIND("/",C2)+1)-FIND("/",C2)-1)))) -> 42593 | E2: =D2 -> 42593 | F2: 42685 | G2: Second Class | H2: CG-12520 | I2: Consumer | J2: United States | K2: Henderson | L2: Kentucky | M2: South | N2: FUR-BO-10001798 | O2: Furniture | P2: Bookcases | Q2: Bush Somerset Collection Bookcase | R2: 261.96 | S2: 2 | T2: 0 | U2: 41.9136
A3: 2 | B3: CA-2016-152156 | C3: 42593 | D3: =IF(ISNUMBER(C3),C3,DATE(VALUE(RIGHT(C3,4)),VALUE(LEFT(C3,FIND("/",C3)-1)),VALUE(MID(C3,FIND("/",C3)+1,FIND("/",C3,FIND("/",C3)+1)-FIND("/",C3)-1)))) -> 42593 | E3: =D3 -> 42593 | F3: 42685 | G3: Second Class | H3: CG-12520 | I3: Consumer | J3: United States | K3: Henderson | L3: Kentucky | M3: South | N3: FUR-CH-10000454 | O3: Furniture | P3: Chairs | Q3: Hon Deluxe Fabric Upholstered Stacking Chairs, Rounded Back | R3: 731.94 | S3: 3 | T3: 0 | U3: 219.582
A4: 3 | B4: CA-2016-138688 | C4: 42710 | D4: =IF(ISNUMBER(C4),C4,DATE(VALUE(RIGHT(C4,4)),VALUE(LEFT(C4,FIND("/",C4)-1)),VALUE(MID(C4,FIND("/",C4)+1,FIND("/",C4,FIND("/",C4)+1)-FIND("/",C4)-1)))) -> 42710 | E4: =D4 -> 42710 | F4: 6/16/2016 | G4: Second Class | H4: DV-13045 | I4: Corporate | J4: United States | K4: Los Angeles | L4: California | M4: West | N4: OFF-LA-10000240 | O4: Office Supplies | P4: Labels | Q4: Self-Adhesive Address Labels for Typewriters by Universal | R4: 14.62 | S4: 2 | T4: 0 | U4: 6.8714
A5: 4 | B5: US-2015-108966 | C5: 42318 | D5: =IF(ISNUMBER(C5),C5,DATE(VALUE(RIGHT(C5,4)),VALUE(LEFT(C5,FIND("/",C5)-1)),VALUE(MID(C5,FIND("/",C5)+1,FIND("/",C5,FIND("/",C5)+1)-FIND("/",C5)-1)))) -> 42318 | E5: =D5 -> 42318 | F5: 10/18/2015 | G5: Standard Class | H5: SO-20335 | I5: Consumer | J5: United States | K5: Fort Lauderdale | L5: Florida | M5: South | N5: FUR-TA-10000577 | O5: Furniture | P5: Tables | Q5: Bretford CR4500 Series Slim Rectangular Table | R5: 957.5775 | S5: 5 | T5: 0.45 | U5: -383.031
A6: 5 | B6: US-2015-108966 | C6: 42318 | D6: =IF(ISNUMBER(C6),C6,DATE(VALUE(RIGHT(C6,4)),VALUE(LEFT(C6,FIND("/",C6)-1)),VALUE(MID(C6,FIND("/",C6)+1,FIND("/",C6,FIND("/",C6)+1)-FIND("/",C6)-1)))) -> 42318 | E6: =D6 -> 42318 | F6: 10/18/2015 | G6: Standard Class | H6: SO-20335 | I6: Consumer | J6: United States | K6: Fort Lauderdale | L6: Florida | M6: South | N6: OFF-ST-10000760 | O6: Office Supplies | P6: Storage | Q6: Eldon Fold 'N Roll Cart System | R6: 22.368 | S6: 2 | T6: 0.2 | U6: 2.5164
A7: 6 | B7: CA-2014-115812 | C7: 41888 | D7: =IF(ISNUMBER(C7),C7,DATE(VALUE(RIGHT(C7,4)),VALUE(LEFT(C7,FIND("/",C7)-1)),VALUE(MID(C7,FIND("/",C7)+1,FIND("/",C7,FIND("/",C7)+1)-FIND("/",C7)-1)))) -> 41888 | E7: =D7 -> 41888 | F7: 6/14/2014 | G7: Standard Class | H7: BH-11710 | I7: Consumer | J7: United States | K7: Los Angeles | L7: California | M7: West | N7: FUR-FU-10001487 | O7: Furniture | P7: Furnishings | Q7: Eldon Expressions Wood and Plastic Desk Accessories, Cherry Wood | R7: 48.86 | S7: 7 | T7: 0 | U7: 14.1694
A8: 7 | B8: CA-2014-115812 | C8: 41888 | D8: =IF(ISNUMBER(C8),C8,DATE(VALUE(RIGHT(C8,4)),VALUE(LEFT(C8,FIND("/",C8)-1)),VALUE(MID(C8,FIND("/",C8)+1,FIND("/",C8,FIND("/",C8)+1)-FIND("/",C8)-1)))) -> 41888 | E8: =D8 -> 41888 | F8: 6/14/2014 | G8: Standard Class | H8: BH-11710 | I8: Consumer | J8: United States | K8: Los Angeles | L8: California | M8: West | N8: OFF-AR-10002833 | O8: Office Supplies | P8: Art | Q8: Newell 322 | R8: 7.28 | S8: 4 | T8: 0 | U8: 1.9656
A9: 8 | B9: CA-2014-115812 | C9: 41888 | D9: =IF(ISNUMBER(C9),C9,DATE(VALUE(RIGHT(C9,4)),VALUE(LEFT(C9,FIND("/",C9)-1)),VALUE(MID(C9,FIND("/",C9)+1,FIND("/",C9,FIND("/",C9)+1)-FIND("/",C9)-1)))) -> 41888 | E9: =D9 -> 41888 | F9: 6/14/2014 | G9: Standard Class | H9: BH-11710 | I9: Consumer | J9: United States | K9: Los Angeles | L9: California | M9: West | N9: TEC-PH-10002275 | O9: Technology | P9: Phones | Q9: Mitel 5320 IP Phone VoIP phone | R9: 907.152 | S9: 6 | T9: 0.2 | U9: 90.7152 | X9: =ISNUMBER(C16) -> FALSE
A10: 9 | B10: CA-2014-115812 | C10: 41888 | D10: =IF(ISNUMBER(C10),C10,DATE(VALUE(RIGHT(C10,4)),VALUE(LEFT(C10,FIND("/",C10)-1)),VALUE(MID(C10,FIND("/",C10)+1,FIND("/",C10,FIND("/",C10)+1)-FIND("/",C10)-1)))) -> 41888 | E10: =D10 -> 41888 | F10: 6/14/2014 | G10: Standard Class | H10: BH-11710 | I10: Consumer | J10: United States | K10: Los Angeles | L10: California | M10: West | N10: OFF-BI-10003910 | O10: Office Supplies | P10: Binders | Q10: DXL Angle-View Binders with Locking Rings by Samsill | R10: 18.504 | S10: 3 | T10: 0.2 | U10: 5.7825
A11: 10 | B11: CA-2014-115812 | C11: 41888 | D11: =IF(ISNUMBER(C11),C11,DATE(VALUE(RIGHT(C11,4)),VALUE(LEFT(C11,FIND("/",C11)-1)),VALUE(MID(C11,FIND("/",C11)+1,FIND("/",C11,FIND("/",C11)+1)-FIND("/",C11)-1)))) -> 41888 | E11: =D11 -> 41888 | F11: 6/14/2014 | G11: Standard Class | H11: BH-11710 | I11: Consumer | J11: United States | K11: Los Angeles | L11: California | M11: West | N11: OFF-AP-10002892 | O11: Office Supplies | P11: Appliances | Q11: Belkin F5C206VTEL 6 Outlet Surge | R11: 114.9 | S11: 5 | T11: 0 | U11: 34.47
A12: 11 | B12: CA-2014-115812 | C12: 41888 | D12: =IF(ISNUMBER(C12),C12,DATE(VALUE(RIGHT(C12,4)),VALUE(LEFT(C12,FIND("/",C12)-1)),VALUE(MID(C12,FIND("/",C12)+1,FIND("/",C12,FIND("/",C12)+1)-FIND("/",C12)-1)))) -> 41888 | E12: =D12 -> 41888 | F12: 6/14/2014 | G12: Standard Class | H12: BH-11710 | I12: Consumer | J12: United States | K12: Los Angeles | L12: California | M12: West | N12: FUR-TA-10001539 | O12: Furniture | P12: Tables | Q12: Chromcraft Rectangular Conference Tables | R12: 1706.184 | S12: 9 | T12: 0.2 | U12: 85.3092
A13: 12 | B13: CA-2014-115812 | C13: 41888 | D13: =IF(ISNUMBER(C13),C13,DATE(VALUE(RIGHT(C13,4)),VALUE(LEFT(C13,FIND("/",C13)-1)),VALUE(MID(C13,FIND("/",C13)+1,FIND("/",C13,FIND("/",C13)+1)-FIND("/",C13)-1)))) -> 41888 | E13: =D13 -> 41888 | F13: 6/14/2014 | G13: Standard Class | H13: BH-11710 | I13: Consumer | J13: United States | K13: Los Angeles | L13: California | M13: West | N13: TEC-PH-10002033 | O13: Technology | P13: Phones | Q13: Konftel 250 ConferenceÂ phoneÂ - Charcoal black | R13: 911.424 | S13: 4 | T13: 0.2 | U13: 68.3568
A14: 13 | B14: CA-2017-114412 | C14: 4/15/2017 | D14: =IF(ISNUMBER(C14),C14,DATE(VALUE(RIGHT(C14,4)),VALUE(LEFT(C14,FIND("/",C14)-1)),VALUE(MID(C14,FIND("/",C14)+1,FIND("/",C14,FIND("/",C14)+1)-FIND("/",C14)-1)))) -> 42840 | E14: =D14 -> 42840 | F14: 4/20/2017 | G14: Standard Class | H14: AA-10480 | I14: Consumer | J14: United States | K14: Concord | L14: North Carolina | M14: South | N14: OFF-PA-10002365 | O14: Office Supplies | P14: Paper | Q14: Xerox 1967 | R14: 15.552 | S14: 3 | T14: 0.2 | U14: 5.4432
A15: 14 | B15: CA-2016-161389 | C15: 42502 | D15: =IF(ISNUMBER(C15),C15,DATE(VALUE(RIGHT(C15,4)),VALUE(LEFT(C15,FIND("/",C15)-1)),VALUE(MID(C15,FIND("/",C15)+1,FIND("/",C15,FIND("/",C15)+1)-FIND("/",C15)-1)))) -> 42502 | E15: =D15 -> 42502 | F15: 42655 | G15: Standard Class | H15: IM-15070 | I15: Consumer | J15: United States | K15: Seattle | L15: Washington | M15: West | N15: OFF-BI-10003656 | O15: Office Supplies | P15: Binders | Q15: Fellowes PB200 Plastic Comb Binding Machine | R15: 407.976 | S15: 3 | T15: 0.2 | U15: 132.5922
A16: 15 | B16: US-2015-118983 | C16: 11/22/2015 | D16: =IF(ISNUMBER(C16),C16,DATE(VALUE(RIGHT(C16,4)),VALUE(LEFT(C16,FIND("/",C16)-1)),VALUE(MID(C16,FIND("/",C16)+1,FIND("/",C16,FIND("/",C16)+1)-FIND("/",C16)-1)))) -> 42330 | E16: =D16 -> 42330 | F16: 11/26/2015 | G16: Standard Class | H16: HP-14815 | I16: Home Office | J16: United States | K16: Fort Worth | L16: Texas | M16: Central | N16: OFF-AP-10002311 | O16: Office Supplies | P16: Appliances | Q16: Holmes Replacement Filter for HEPA Air Cleaner, Very Large Room, HEPA Filter | R16: 68.81 | S16: 5 | T16: 0.8 | U16: -123.858
A17: 16 | B17: US-2015-118983 | C17: 11/22/2015 | D17: =IF(ISNUMBER(C17),C17,DATE(VALUE(RIGHT(C17,4)),VALUE(LEFT(C17,FIND("/",C17)-1)),VALUE(MID(C17,FIND("/",C17)+1,FIND("/",C17,FIND("/",C17)+1)-FIND("/",C17)-1)))) -> 42330 | E17: =D17 -> 42330 | F17: 11/26/2015 | G17: Standard Class | H17: HP-14815 | I17: Home Office | J17: United States | K17: Fort Worth | L17: Texas | M17: Central | N17: OFF-BI-10000756 | O17: Office Supplies | P17: Binders | Q17: Storex DuraTech Recycled Plastic Frosted Binders | R17: 2.544 | S17: 3 | T17: 0.8 | U17: -3.816
A18: 17 | B18: CA-2014-105893 | C18: 41954 | D18: =IF(ISNUMBER(C18),C18,DATE(VALUE(RIGHT(C18,4)),VALUE(LEFT(C18,FIND("/",C18)-1)),VALUE(MID(C18,FIND("/",C18)+1,FIND("/",C18,FIND("/",C18)+1)-FIND("/",C18)-1)))) -> 41954 | E18: =D18 -> 41954 | F18: 11/18/2014 | G18: Standard Class | H18: PK-19075 | I18: Consumer | J18: United States | K18: Madison | L18: Wisconsin | M18: Central | N18: OFF-ST-10004186 | O18: Office Supplies | P18: Storage | Q18: Stur-D-Stor Shelving, Vertical 5-Shelf: 72"H x 36"W x 18 1/2"D | R18: 665.88 | S18: 6 | T18: 0 | U18: 13.3176
A19: 18 | B19: CA-2014-167164 | C19: 5/13/2014 | D19: =IF(ISNUMBER(C19),C19,DATE(VALUE(RIGHT(C19,4)),VALUE(LEFT(C19,FIND("/",C19)-1)),VALUE(MID(C19,FIND("/",C19)+1,FIND("/",C19,FIND("/",C19)+1)-FIND("/",C19)-1)))) -> 41772 | E19: =D19 -> 41772 | F19: 5/15/2014 | G19: Second Class | H19: AG-10270 | I19: Consumer | J19: United States | K19: West Jordan | L19: Utah | M19: West | N19: OFF-ST-10000107 | O19: Office Supplies | P19: Storage | Q19: Fellowes Super Stor/Drawer | R19: 55.5 | S19: 2 | T19: 0 | U19: 9.99
A20: 19 | B20: CA-2014-143336 | C20: 8/27/2014 | D20: =IF(ISNUMBER(C20),C20,DATE(VALUE(RIGHT(C20,4)),VALUE(LEFT(C20,FIND("/",C20)-1)),VALUE(MID(C20,FIND("/",C20)+1,FIND("/",C20,FIND("/",C20)+1)-FIND("/",C20)-1)))) -> 41878 | E20: =D20 -> 41878 | F20: 41648 | G20: Second Class | H20: ZD-21925 | I20: Consumer | J20: United States | K20: San Francisco | L20: California | M20: West | N20: OFF-AR-10003056 | O20: Office Supplies | P20: Art | Q20: Newell 341 | R20: 8.56 | S20: 2 | T20: 0 | U20: 2.4824
A21: 20 | B21: CA-2014-143336 | C21: 8/27/2014 | D21: =IF(ISNUMBER(C21),C21,DATE(VALUE(RIGHT(C21,4)),VALUE(LEFT(C21,FIND("/",C21)-1)),VALUE(MID(C21,FIND("/",C21)+1,FIND("/",C21,FIND("/",C21)+1)-FIND("/",C21)-1)))) -> 41878 | E21: =D21 -> 41878 | F21: 41648 | G21: Second Class | H21: ZD-21925 | I21: Consumer | J21: United States | K21: San Francisco | L21: California | M21: West | N21: TEC-PH-10001949 | O21: Technology | P21: Phones | Q21: Cisco SPA 501G IP Phone | R21: 213.48 | S21: 3 | T21: 0.2 | U21: 16.011
A22: 21 | B22: CA-2014-143336 | C22: 8/27/2014 | D22: =IF(ISNUMBER(C22),C22,DATE(VALUE(RIGHT(C22,4)),VALUE(LEFT(C22,FIND("/",C22)-1)),VALUE(MID(C22,FIND("/",C22)+1,FIND("/",C22,FIND("/",C22)+1)-FIND("/",C22)-1)))) -> 41878 | E22: =D22 -> 41878 | F22: 41648 | G22: Second Class | H22: ZD-21925 | I22: Consumer | J22: United States | K22: San Francisco | L22: California | M22: West | N22: OFF-BI-10002215 | O22: Office Supplies | P22: Binders | Q22: Wilson Jones Hanging View Binder, White, 1" | R22: 22.72 | S22: 4 | T22: 0.2 | U22: 7.384
A23: 22 | B23: CA-2016-137330 | C23: 42625 | D23: =IF(ISNUMBER(C23),C23,DATE(VALUE(RIGHT(C23,4)),VALUE(LEFT(C23,FIND("/",C23)-1)),VALUE(MID(C23,FIND("/",C23)+1,FIND("/",C23,FIND("/",C23)+1)-FIND("/",C23)-1)))) -> 42625 | E23: =D23 -> 42625 | F23: 12/13/2016 | G23: Standard Class | H23: KB-16585 | I23: Corporate | J23: United States | K23: Fremont | L23: Nebraska | M23: Central | N23: OFF-AR-10000246 | O23: Office Supplies | P23: Art | Q23: Newell 318 | R23: 19.46 | S23: 7 | T23: 0 | U23: 5.0596
A24: 23 | B24: CA-2016-137330 | C24: 42625 | D24: =IF(ISNUMBER(C24),C24,DATE(VALUE(RIGHT(C24,4)),VALUE(LEFT(C24,FIND("/",C24)-1)),VALUE(MID(C24,FIND("/",C24)+1,FIND("/",C24,FIND("/",C24)+1)-FIND("/",C24)-1)))) -> 42625 | E24: =D24 -> 42625 | F24: 12/13/2016 | G24: Standard Class | H24: KB-16585 | I24: Corporate | J24: United States | K24: Fremont | L24: Nebraska | M24: Central | N24: OFF-AP-10001492 | O24: Office Supplies | P24: Appliances | Q24: Acco Six-Outlet Power Strip, 4' Cord Length | R24: 60.34 | S24: 7 | T24: 0 | U24: 15.6884
A25: 24 | B25: US-2017-156909 | C25: 7/16/2017 | D25: =IF(ISNUMBER(C25),C25,DATE(VALUE(RIGHT(C25,4)),VALUE(LEFT(C25,FIND("/",C25)-1)),VALUE(MID(C25,FIND("/",C25)+1,FIND("/",C25,FIND("/",C25)+1)-FIND("/",C25)-1)))) -> 42932 | E25: =D25 -> 42932 | F25: 7/18/2017 | G25: Second Class | H25: SF-20065 | I25: Consumer | J25: United States | K25: Philadelphia | L25: Pennsylvania | M25: East | N25: FUR-CH-10002774 | O25: Furniture | P25: Chairs | Q25: Global Deluxe Stacking Chair, Gray | R25: 71.372 | S25: 2 | T25: 0.3 | U25: -1.0196
A26: 25 | B26: CA-2015-106320 | C26: 9/25/2015 | D26: =IF(ISNUMBER(C26),C26,DATE(VALUE(RIGHT(C26,4)),VALUE(LEFT(C26,FIND("/",C26)-1)),VALUE(MID(C26,FIND("/",C26)+1,FIND("/",C26,FIND("/",C26)+1)-FIND("/",C26)-1)))) -> 42272 | E26: =D26 -> 42272 | F26: 9/30/2015 | G26: Standard Class | H26: EB-13870 | I26: Consumer | J26: United States | K26: Orem | L26: Utah | M26: West | N26: FUR-TA-10000577 | O26: Furniture | P26: Tables | Q26: Bretford CR4500 Series Slim Rectangular Table | R26: 1044.63 | S26: 3 | T26: 0 | U26: 240.2649
A27: 26 | B27: CA-2016-121755 | C27: 1/16/2016 | D27: =IF(ISNUMBER(C27),C27,DATE(VALUE(RIGHT(C27,4)),VALUE(LEFT(C27,FIND("/",C27)-1)),VALUE(MID(C27,FIND("/",C27)+1,FIND("/",C27,FIND("/",C27)+1)-FIND("/",C27)-1)))) -> 42385 | E27: =D27 -> 42385 | F27: 1/20/2016 | G27: Second Class | H27: EH-13945 | I27: Consumer | J27: United States | K27: Los Angeles | L27: California | M27: West | N27: OFF-BI-10001634 | O27: Office Supplies | P27: Binders | Q27: Wilson Jones Active Use Binders | R27: 11.648 | S27: 2 | T27: 0.2 | U27: 4.2224
A28: 27 | B28: CA-2016-121755 | C28: 1/16/2016 | D28: =IF(ISNUMBER(C28),C28,DATE(VALUE(RIGHT(C28,4)),VALUE(LEFT(C28,FIND("/",C28)-1)),VALUE(MID(C28,FIND("/",C28)+1,FIND("/",C28,FIND("/",C28)+1)-FIND("/",C28)-1)))) -> 42385 | E28: =D28 -> 42385 | F28: 1/20/2016 | G28: Second Class | H28: EH-13945 | I28: Consumer | J28: United States | K28: Los Angeles | L28: California | M28: West | N28: TEC-AC-10003027 | O28: Technology | P28: Accessories | Q28: ImationÂ 8GB Mini TravelDrive USB 2.0Â Flash Drive | R28: 90.57 | S28: 3 | T28: 0 | U28: 11.7741
A29: 28 | B29: US-2015-150630 | C29: 9/17/2015 | D29: =IF(ISNUMBER(C29),C29,DATE(VALUE(RIGHT(C29,4)),VALUE(LEFT(C29,FIND("/",C29)-1)),VALUE(MID(C29,FIND("/",C29)+1,FIND("/",C29,FIND("/",C29)+1)-FIND("/",C29)-1)))) -> 42264 | E29: =D29 -> 42264 | F29: 9/21/2015 | G29: Standard Class | H29: TB-21520 | I29: Consumer | J29: United States | K29: Philadelphia | L29: Pennsylvania | M29: East | N29: FUR-BO-10004834 | O29: Furniture | P29: Bookcases | Q29: Riverside Palais Royal Lawyers Bookcase, Royale Cherry Finish | R29: 3083.43 | S29: 7 | T29: 0.5 | U29: -1665.0522
A30: 29 | B30: US-2015-150630 | C30: 9/17/2015 | D30: =IF(ISNUMBER(C30),C30,DATE(VALUE(RIGHT(C30,4)),VALUE(LEFT(C30,FIND("/",C30)-1)),VALUE(MID(C30,FIND("/",C30)+1,FIND("/",C30,FIND("/",C30)+1)-FIND("/",C30)-1)))) -> 42264 | E30: =D30 -> 42264 | F30: 9/21/2015 | G30: Standard Class | H30: TB-21520 | I30: Consumer | J30: United States | K30: Philadelphia | L30: Pennsylvania | M30: East | N30: OFF-BI-10000474 | O30: Office Supplies | P30: Binders | Q30: Avery Recycled Flexi-View Covers for Binding Systems | R30: 9.618 | S30: 2 | T30: 0.7 | U30: -7.0532
A31: 30 | B31: US-2015-150630 | C31: 9/17/2015 | D31: =IF(ISNUMBER(C31),C31,DATE(VALUE(RIGHT(C31,4)),VALUE(LEFT(C31,FIND("/",C31)-1)),VALUE(MID(C31,FIND("/",C31)+1,FIND("/",C31,FIND("/",C31)+1)-FIND("/",C31)-1)))) -> 42264 | E31: =D31 -> 42264 | F31: 9/21/2015 | G31: Standard Class | H31: TB-21520 | I31: Consumer | J31: United States | K31: Philadelphia | L31: Pennsylvania | M31: East | N31: FUR-FU-10004848 | O31: Furniture | P31: Furnishings | Q31: Howard Miller 13-3/4" Diameter Brushed Chrome Round Wall Clock | R31: 124.2 | S31: 3 | T31: 0.2 | U31: 15.525
A32: 31 | B32: US-2015-150630 | C32: 9/17/2015 | D32: =IF(ISNUMBER(C32),C32,DATE(VALUE(RIGHT(C32,4)),VALUE(LEFT(C32,FIND("/",C32)-1)),VALUE(MID(C32,FIND("/",C32)+1,FIND("/",C32,FIND("/",C32)+1)-FIND("/",C32)-1)))) -> 42264 | E32: =D32 -> 42264 | F32: 9/21/2015 | G32: Standard Class | H32: TB-21520 | I32: Consumer | J32: United States | K32: Philadelphia | L32: Pennsylvania | M32: East | N32: OFF-EN-10001509 | O32: Office Supplies | P32: Envelopes | Q32: Poly String Tie Envelopes | R32: 3.264 | S32: 2 | T32: 0.2 | U32: 1.1016
A33: 32 | B33: US-2015-150630 | C33: 9/17/2015 | D33: =IF(ISNUMBER(C33),C33,DATE(VALUE(RIGHT(C33,4)),VALUE(LEFT(C33,FIND("/",C33)-1)),VALUE(MID(C33,FIND("/",C33)+1,FIND("/",C33,FIND("/",C33)+1)-FIND("/",C33)-1)))) -> 42264 | E33: =D33 -> 42264 | F33: 9/21/2015 | G33: Standard Class | H33: TB-21520 | I33: Consumer | J33: United States | K33: Philadelphia | L33: Pennsylvania | M33: East | N33: OFF-AR-10004042 | O33: Office Supplies | P33: Art | Q33: BOSTON Model 1800 Electric Pencil Sharpeners, Putty/Woodgrain | R33: 86.304 | S33: 6 | T33: 0.2 | U33: 9.7092
A34: 33 | B34: US-2015-150630 | C34: 9/17/2015 | D34: =IF(ISNUMBER(C34),C34,DATE(VALUE(RIGHT(C34,4)),VALUE(LEFT(C34,FIND("/",C34)-1)),VALUE(MID(C34,FIND("/",C34)+1,FIND("/",C34,FIND("/",C34)+1)-FIND("/",C34)-1)))) -> 42264 | E34: =D34 -> 42264 | F34: 9/21/2015 | G34: Standard Class | H34: TB-21520 | I34: Consumer | J34: United States | K34: Philadelphia | L34: Pennsylvania | M34: East | N34: OFF-BI-10001525 | O34: Office Supplies | P34: Binders | Q34: Acco Pressboard Covers with Storage Hooks, 14 7/8" x 11", Executive Red | R34: 6.858 | S34: 6 | T34: 0.7 | U34: -5.715
A35: 34 | B35: US-2015-150630 | C35: 9/17/2015 | D35: =IF(ISNUMBER(C35),C35,DATE(VALUE(RIGHT(C35,4)),VALUE(LEFT(C35,FIND("/",C35)-1)),VALUE(MID(C35,FIND("/",C35)+1,FIND("/",C35,FIND("/",C35)+1)-FIND("/",C35)-1)))) -> 42264 | E35: =D35 -> 42264 | F35: 9/21/2015 | G35: Standard Class | H35: TB-21520 | I35: Consumer | J35: United States | K35: Philadelphia | L35: Pennsylvania | M35: East | N35: OFF-AR-10001683 | O35: Office Supplies | P35: Art | Q35: Lumber Crayons | R35: 15.76 | S35: 2 | T35: 0.2 | U35: 3.546
A36: 35 | B36: CA-2017-107727 | C36: 10/19/2017 | D36: =IF(ISNUMBER(C36),C36,DATE(VALUE(RIGHT(C36,4)),VALUE(LEFT(C36,FIND("/",C36)-1)),VALUE(MID(C36,FIND("/",C36)+1,FIND("/",C36,FIND("/",C36)+1)-FIND("/",C36)-1)))) -> 43027 | E36: =D36 -> 43027 | F36: 10/23/2017 | G36: Second Class | H36: MA-17560 | I36: Home Office | J36: United States | K36: Houston | L36: Texas | M36: Central | N36: OFF-PA-10000249 | O36: Office Supplies | P36: Paper | Q36: Easy-staple paper | R36: 29.472 | S36: 3 | T36: 0.2 | U36: 9.9468
A37: 36 | B37: CA-2016-117590 | C37: 42594 | D37: =IF(ISNUMBER(C37),C37,DATE(VALUE(RIGHT(C37,4)),VALUE(LEFT(C37,FIND("/",C37)-1)),VALUE(MID(C37,FIND("/",C37)+1,FIND("/",C37,FIND("/",C37)+1)-FIND("/",C37)-1)))) -> 42594 | E37: =D37 -> 42594 | F37: 42655 | G37: First Class | H37: GH-14485 | I37: Corporate | J37: United States | K37: Richardson | L37: Texas | M37: Central | N37: TEC-PH-10004977 | O37: Technology | P37: Phones | Q37: GE 30524EE4 | R37: 1097.544 | S37: 7 | T37: 0.2 | U37: 123.4737
A38: 37 | B38: CA-2016-117590 | C38: 42594 | D38: =IF(ISNUMBER(C38),C38,DATE(VALUE(RIGHT(C38,4)),VALUE(LEFT(C38,FIND("/",C38)-1)),VALUE(MID(C38,FIND("/",C38)+1,FIND("/",C38,FIND("/",C38)+1)-FIND("/",C38)-1)))) -> 42594 | E38: =D38 -> 42594 | F38: 42655 | G38: First Class | H38: GH-14485 | I38: Corporate | J38: United States | K38: Richardson | L38: Texas | M38: Central | N38: FUR-FU-10003664 | O38: Furniture | P38: Furnishings | Q38: Electrix Architect's Clamp-On Swing Arm Lamp, Black | R38: 190.92 | S38: 5 | T38: 0.6 | U38: -147.963
A39: 38 | B39: CA-2015-117415 | C39: 12/27/2015 | D39: =IF(ISNUMBER(C39),C39,DATE(VALUE(RIGHT(C39,4)),VALUE(LEFT(C39,FIND("/",C39)-1)),VALUE(MID(C39,FIND("/",C39)+1,FIND("/",C39,FIND("/",C39)+1)-FIND("/",C39)-1)))) -> 42365 | E39: =D39 -> 42365 | F39: 12/31/2015 | G39: Standard Class | H39: SN-20710 | I39: Home Office | J39: United States | K39: Houston | L39: Texas | M39: Central | N39: OFF-EN-10002986 | O39: Office Supplies | P39: Envelopes | Q39: #10-4 1/8" x 9 1/2" Premium Diagonal Seam Envelopes | R39: 113.328 | S39: 9 | T39: 0.2 | U39: 35.415
A40: 39 | B40: CA-2015-117415 | C40: 12/27/2015 | D40: =IF(ISNUMBER(C40),C40,DATE(VALUE(RIGHT(C40,4)),VALUE(LEFT(C40,FIND("/",C40)-1)),VALUE(MID(C40,FIND("/",C40)+1,FIND("/",C40,FIND("/",C40)+1)-FIND("/",C40)-1)))) -> 42365 | E40: =D40 -> 42365 | F40: 12/31/2015 | G40: Standard Class | H40: SN-20710 | I40: Home Office | J40: United States | K40: Houston | L40: Texas | M40: Central | N40: FUR-BO-10002545 | O40: Furniture | P40: Bookcases | Q40: Atlantic Metals Mobile 3-Shelf Bookcases, Custom Colors | R40: 532.3992 | S40: 3 | T40: 0.32 | U40: -46.9764
...

Sheet Summary
A1: Month | B1: Total Sales
A2: 41640 | B2: =SUMIFS('Raw Data'!R:R,'Raw Data'!E:E,">="&A2,'Raw Data'!E:E,"<"&EDATE(A2,1)) -> 28953.706
A3: 41671 | B3: =SUMIFS('Raw Data'!R:R,'Raw Data'!E:E,">="&A3,'Raw Data'!E:E,"<"&EDATE(A3,1)) -> 12743.108
A4: 41699 | B4: =SUMIFS('Raw Data'!R:R,'Raw Data'!E:E,">="&A4,'Raw Data'!E:E,"<"&EDATE(A4,1)) -> 54801.906
A5: 41730 | B5: =SUMIFS('Raw Data'!R:R,'Raw Data'!E:E,">="&A5,'Raw Data'!E:E,"<"&EDATE(A5,1)) -> 24710.016
A6: 41760 | B6: =SUMIFS('Raw Data'!R:R,'Raw Data'!E:E,">="&A6,'Raw Data'!E:E,"<"&EDATE(A6,1)) -> 29639.834
A7: 41791 | B7: =SUMIFS('Raw Data'!R:R,'Raw Data'!E:E,">="&A7,'Raw Data'!E:E,"<"&EDATE(A7,1)) -> 29287.031
A8: 41821 | B8: =SUMIFS('Raw Data'!R:R,'Raw Data'!E:E,">="&A8,'Raw Data'!E:E,"<"&EDATE(A8,1)) -> 35341.246 | Y8: Metric | Z8: Result
A9: 41852 | B9: =SUMIFS('Raw Data'!R:R,'Raw Data'!E:E,">="&A9,'Raw Data'!E:E,"<"&EDATE(A9,1)) -> 37854.547 | Y9: Highest Sales Month | Z9: 43040
A10: 41883 | B10: =SUMIFS('Raw Data'!R:R,'Raw Data'!E:E,">="&A10,'Raw Data'!E:E,"<"&EDATE(A10,1)) -> 66110.224 | Y10: Highest Monthly Sales | Z10: 89306.24
A11: 41913 | B11: =SUMIFS('Raw Data'!R:R,'Raw Data'!E:E,">="&A11,'Raw Data'!E:E,"<"&EDATE(A11,1)) -> 34561.947 | Y11: Lowest Sales Month | Z11: 42036
A12: 41944 | B12: =SUMIFS('Raw Data'!R:R,'Raw Data'!E:E,">="&A12,'Raw Data'!E:E,"<"&EDATE(A12,1)) -> 64817.619 | Y12: Lowest Monthly Sales | Z12: 20728.35
A13: 41974 | B13: =SUMIFS('Raw Data'!R:R,'Raw Data'!E:E,">="&A13,'Raw Data'!E:E,"<"&EDATE(A13,1)) -> 65426.315
A14: 42005 | B14: =SUMIFS('Raw Data'!R:R,'Raw Data'!E:E,">="&A14,'Raw Data'!E:E,"<"&EDATE(A14,1)) -> 29347.386
A15: 42036 | B15: =SUMIFS('Raw Data'!R:R,'Raw Data'!E:E,">="&A15,'Raw Data'!E:E,"<"&EDATE(A15,1)) -> 20728.352
A16: 42064 | B16: =SUMIFS('Raw Data'!R:R,'Raw Data'!E:E,">="&A16,'Raw Data'!E:E,"<"&EDATE(A16,1)) -> 40876.611
A17: 42095 | B17: =SUMIFS('Raw Data'!R:R,'Raw Data'!E:E,">="&A17,'Raw Data'!E:E,"<"&EDATE(A17,1)) -> 38056.969
A18: 42125 | B18: =SUMIFS('Raw Data'!R:R,'Raw Data'!E:E,">="&A18,'Raw Data'!E:E,"<"&EDATE(A18,1)) -> 30933.715 | Y18: Year | Z18: Total Sales
A19: 42156 | B19: =SUMIFS('Raw Data'!R:R,'Raw Data'!E:E,">="&A19,'Raw Data'!E:E,"<"&EDATE(A19,1)) -> 28862.198 | Y19: 2014 | Z19: =SUMIFS($B$2:$B$49,$A$2:$A$49,">="&DATE(Y19,1,1),$A$2:$A$49,"<"&DATE(Y19+1,1,1)) -> 484247.5
A20: 42186 | B20: =SUMIFS('Raw Data'!R:R,'Raw Data'!E:E,">="&A20,'Raw Data'!E:E,"<"&EDATE(A20,1)) -> 28730.376 | Y20: 2015 | Z20: =SUMIFS($B$2:$B$49,$A$2:$A$49,">="&DATE(Y20,1,1),$A$2:$A$49,"<"&DATE(Y20+1,1,1)) -> 470532.51
A21: 42217 | B21: =SUMIFS('Raw Data'!R:R,'Raw Data'!E:E,">="&A21,'Raw Data'!E:E,"<"&EDATE(A21,1)) -> 50094.528 | Y21: 2016 | Z21: =SUMIFS($B$2:$B$49,$A$2:$A$49,">="&DATE(Y21,1,1),$A$2:$A$49,"<"&DATE(Y21+1,1,1)) -> 609205.6
A22: 42248 | B22: =SUMIFS('Raw Data'!R:R,'Raw Data'!E:E,">="&A22,'Raw Data'!E:E,"<"&EDATE(A22,1)) -> 66729.329 | Y22: 2017 | Z22: =SUMIFS($B$2:$B$49,$A$2:$A$49,">="&DATE(Y22,1,1),$A$2:$A$49,"<"&DATE(Y22+1,1,1)) -> 733215.26
A23: 42278 | B23: =SUMIFS('Raw Data'!R:R,'Raw Data'!E:E,">="&A23,'Raw Data'!E:E,"<"&EDATE(A23,1)) -> 32025.075
A24: 42309 | B24: =SUMIFS('Raw Data'!R:R,'Raw Data'!E:E,">="&A24,'Raw Data'!E:E,"<"&EDATE(A24,1)) -> 50732.309
A25: 42339 | B25: =SUMIFS('Raw Data'!R:R,'Raw Data'!E:E,">="&A25,'Raw Data'!E:E,"<"&EDATE(A25,1)) -> 53415.661
A26: 42370 | B26: =SUMIFS('Raw Data'!R:R,'Raw Data'!E:E,">="&A26,'Raw Data'!E:E,"<"&EDATE(A26,1)) -> 38048.184
A27: 42401 | B27: =SUMIFS('Raw Data'!R:R,'Raw Data'!E:E,">="&A27,'Raw Data'!E:E,"<"&EDATE(A27,1)) -> 49238.41
A28: 42430 | B28: =SUMIFS('Raw Data'!R:R,'Raw Data'!E:E,">="&A28,'Raw Data'!E:E,"<"&EDATE(A28,1)) -> 49612.045
A29: 42461 | B29: =SUMIFS('Raw Data'!R:R,'Raw Data'!E:E,">="&A29,'Raw Data'!E:E,"<"&EDATE(A29,1)) -> 45192.278
A30: 42491 | B30: =SUMIFS('Raw Data'!R:R,'Raw Data'!E:E,">="&A30,'Raw Data'!E:E,"<"&EDATE(A30,1)) -> 64964.322 | X30: Overall sales trend: Sales show fluctuations month-to-month, but the later years generally contain higher monthly sales values.
A31: 42522 | B31: =SUMIFS('Raw Data'!R:R,'Raw Data'!E:E,">="&A31,'Raw Data'!E:E,"<"&EDATE(A31,1)) -> 38991.943 | X31: Highest sales month: November 2017 recorded the highest monthly sales of ₹89,306.24.
A32: 42552 | B32: =SUMIFS('Raw Data'!R:R,'Raw Data'!E:E,">="&A32,'Raw Data'!E:E,"<"&EDATE(A32,1)) -> 42773.395 | X32: Lowest sales month: February 2015 recorded the lowest monthly sales of ₹20,728.35.
A33: 42583 | B33: =SUMIFS('Raw Data'!R:R,'Raw Data'!E:E,">="&A33,'Raw Data'!E:E,"<"&EDATE(A33,1)) -> 46339.988 | X33: Yearly performance: 2017 recorded the highest annual sales among the four years, while 2015 was lower than 2014.
A34: 42614 | B34: =SUMIFS('Raw Data'!R:R,'Raw Data'!E:E,">="&A34,'Raw Data'!E:E,"<"&EDATE(A34,1)) -> 41985.142 | X34: Monthly variation: Sales fluctuate considerably across months, indicating that sales performance is not uniform throughout the year.
A35: 42644 | B35: =SUMIFS('Raw Data'!R:R,'Raw Data'!E:E,">="&A35,'Raw Data'!E:E,"<"&EDATE(A35,1)) -> 52268.15
A36: 42675 | B36: =SUMIFS('Raw Data'!R:R,'Raw Data'!E:E,">="&A36,'Raw Data'!E:E,"<"&EDATE(A36,1)) -> 66837.585
A37: 42705 | B37: =SUMIFS('Raw Data'!R:R,'Raw Data'!E:E,">="&A37,'Raw Data'!E:E,"<"&EDATE(A37,1)) -> 72954.156
A38: 42736 | B38: =SUMIFS('Raw Data'!R:R,'Raw Data'!E:E,">="&A38,'Raw Data'!E:E,"<"&EDATE(A38,1)) -> 64734.311
A39: 42767 | B39: =SUMIFS('Raw Data'!R:R,'Raw Data'!E:E,">="&A39,'Raw Data'!E:E,"<"&EDATE(A39,1)) -> 50011.489
A40: 42795 | B40: =SUMIFS('Raw Data'!R:R,'Raw Data'!E:E,">="&A40,'Raw Data'!E:E,"<"&EDATE(A40,1)) -> 74774.084
...
